Workbook

Sheet Navigator 
B2: EduVista Strategic Pivot — Unit Economics Financial Model
B3: Series B EdTech | IIT-JEE Coaching | Tier 2 India | April 2026 | Built by Soham Pawar
B5: 🔵 BLUE = Input — change these | C5: ⬛ BLACK = Formula — do not type over | D5: 🟢 GREEN = Output / Result
B7: Sheet | C7: What it Shows | D7: Key Ouput
B8: 📊 Assumptions | C8: All hardcoded inputs. Change ONLY here. | D8: Central input hub
B9: 🔢 Unit Economics | C9: LTV, CAC, Payback, LTV/CAC ratio — current vs target | D9: LTV/CAC 0.37x → 1.97x
B10: 📈 P&L Model | C10: Month-by-month revenue, COGS, contribution margin | D10: Breakeven Month 5 ✅
B11: ⚖️ Scenario Comparison | C11: Option A vs B vs C on 10 metrics | D11: Option B RECOMMENDED
B12: 🔬 Sensitivity Analysis | C12: LTV/CAC heatmap + Breakeven heatmap | D12: Risk map (red→green)
B13: 📊 Competitive Intel | C13: PW / Unacademy / Allen vs EduVista target | D13: Gap analysis
B15: Built by: Soham Pawar | Final Year Engineering Student → Consulting Track Skills demonstrated: Financial Modelling · Unit Economics · Sensitivity Analysis · Data Visualization

Sheet Assumptions
B2: EduVista Strategic Pivot — Assumptions Dashboard
B3: Series B EdTech Turnaround | IIT-JEE Coaching | Tier 2 India | April 2026
B5: Blue cells = inputs. Change ONLY these. Formulas in other sheets auto-update.
B7: 🔵 BLUE = Input — change these | C7: ⬛ BLACK = Formula — do not type over | D7: 🟢 GREEN = Output / Result
B9: SECTION A — CURRENT STATE (Pre-Pivot)
B10: Assumption | C10: Current Value | D10: Unit | E10: Source / Note
B11: B (Parameter) | C11: C (Value) | D11: D (Unit) | E11: E (Source)
B12: Monthly Burn Rate | C12: 32000000 | D12: ₹ / month | E12: EduVista Case
B13: Cash Runway Remaining | C13: 6 | D13: Months | E13: Critical constraint
B14: Active Students (Current) | C14: 2400 | D14: Students | E14: EduVista Case
B15: Monthly ARPU — Online | C15: 4200 | D15: ₹ / student / month | E15: EduVista Case
B16: Customer Acquisition Cost (CAC) | C16: 18000 | D16: ₹ / new student | E16: Blended paid + organic
B17: 6-Month Retention Rate | C17: 0.42 | D17: Format as % → shows 42% | E17: EduVista Case
B18: Gross Margin % — Current | C18: 0.38 | D18: Format as % → 38% | E18: After teacher + platform
B19: Average Customer Lifetime | C19: 4.2 | D19: Months | E19: 1/(1−monthly churn)
B20: Lifetime Value (LTV) — Current | C20: =C15*C18*C19 -> 6703.2 | D20: ₹ | E20: ARPU × GM % x Lifetime
B21: LTV − CAC (Net) | C21: =C20-C16 -> -11296.8 | D21: ₹ | E21: 6,703 − 18,000 ⚠️
B22: LTV/CAC Ratio — Current | C22: =C20/C16 -> 0.3724 | D22: × | E22: Threshold = 3x
B24: SECTION B — TARGET STATE (Option B: Phygital Lite — RECOMMENDED)
B25: Assumption | C25: Current Value | D25: Unit | E25: Source / Note
B26: Parameter | C26: Value | D26: Unit | E26: Source
B27: Target Monthly ARPU | C27: 4800 | D27: ₹ / month | E27: +₹600 hybrid premium
B28: Target CAC (Post-Pivot) | C28: 10800 | D28: ₹ / student | E28: −40% via referral shift
B29: Target 6-Month Retention | C29: 0.55 | D29: % (55%) | E29: +13pp via peer groups
B30: Target Gross Margin % | C30: 0.52 | D30: % (52%) | E30: Post cost optimization
B31: Monthly Growth Rate (M3–M12) | C31: 0.15 | D31: % (15%) | E31: Conservative assumption
B32: Target Avg Customer Lifetime | C32: 8.5 | D32: Months | E32: Derived from 55% retention
B33: Target LTV | C33: =C27*C30*C32 -> 21216 | D33: ₹ | E33: ₹4,800 × 52% × 8.5 mo
B34: Target LTV/CAC | C34: =C33/C28 -> 1.9644444 | D34: × | E34: 21,216 ÷ 10,800
B36: SECTION C — Phygital Lite COSTS
B37: Assumption | C37: Current Value | D37: Unit | E37: Source / Note
B38: Parameter | C38: Value | D38: Unit | E38: Source
B39: No. of Pilot Cities | C39: 5 | D39: Cities | E39: Jaipur/Lucknow/Indore/Surat/Bhopal
B40: Venue Rent / City / Month | C40: 80000 | D40: ₹ | E40: Weekend hub rental
B41: Facilitator Cost / City / Month | C41: 35000 | D41: ₹ | E41: Local facilitators
B42: One-Time Setup CapEx | C42: 500000 | D42: ₹ total | E42: Venue fit-out
B43: Monthly Fixed OpEx (Total) | C43: 3200000 | D43: ₹ / month | E43: Salaries + Tech + G&A
B45: SECTION C — CAC CHANNEL MIX ASSUMPTIONS
B46: Channel | C46: Current Mix % | D46: Target Mix % | E46: CAC (₹)
B47: Meta/Google Ads (Paid) | C47: 0.75 | D47: 0.25 | E47: 22000
...

Sheet  Unit Economics
B2: Unit Economics Calculator — Live Online vs. Phygital Lite
B3: All formulas link to Assumptions sheet. Change blue inputs there to update everything here.
B5: Formula: LTV = ARPU × Gross Margin × Avg Lifetime | Threshold: LTV/CAC ≥ 1.96x
B7: Metric | C7: Formula Used | D7: CURRENT (Pre-Pivot) | E7: TARGET (Option B) | F7: Delta / Change
B8: REVENUE METRICS
B9: Monthly ARPU (₹) | C9: Direct input | D9: =Assumptions!C15 -> 4200 | E9: =Assumptions!C27 -> 4800 | F9: =E9-D9 -> 600
B10: Gross Margin % | C10: Revenue − COGS / Revenue | D10: =Assumptions!C18 -> 0.38 | E10: =Assumptions!C30 -> 0.52 | F10: =E10-D10 -> 0.14
B11: Monthly Gross Profit/Student | C11: ARPU × Gross Margin | D11: =D9*D10 -> 1596 | E11: =E9*E10 -> 2496 | F11: =E11-D11 -> 900
B12: 6-Month Retention Rate | C12: Cohort survival | D12: =Assumptions!C17 -> 0.42 | E12: =Assumptions!C29 -> 0.55 | F12: =E12-D12 -> 0.13
B13: Avg Customer Lifetime | C13: Derived from churn | D13: =Assumptions!C19 -> 4.2 | E13: =Assumptions!C32 -> 8.5 | F13: =E13-D13 -> 4.3
B15: ACQUISITION & LTV
B16: Customer Acquisition Cost (CAC) | C16: Blended paid + organic | D16: =Assumptions!C16 -> 18000 | E16: =Assumptions!C28 -> 10800 | F16: =E16-D16 -> -7200
B17: Lifetime Value (LTV) — Current | C17: ARPU × Lifetime | D17: =Assumptions!C20 -> 6703.2 | E17: =Assumptions!C33 -> 21216 | F17: =E17-D17 -> 14512.8
B18: LTV − CAC (Net) | C18: LTV minus CAC | D18: =Assumptions!C21 -> -11296.8 | E18: =Assumptions!C33-Assumptions!C28 -> 10416 | F18: =E18-D18 -> 21712.8
B20: KEY RATIOS (Benchmark: LTV/CAC ≥ 3x, Payback ≤ 12 months)
B21: LTV/CAC Ratio — Current | C21: LTV/CAC | D21: =Assumptions!C22 -> 0.3724 | E21: =Assumptions!C34 -> 1.9644444 | F21: Phase 2 Goal : 5x
B22: CAC Payback Period | C22: CAC ÷ (ARPU × GM%) | D22: =D16/(D9*D10) -> 11.278195 | E22: =E16/(E9*E10) -> 4.3269231 | F22: =E22-D22 -> -6.9512724
B23: Contribution/Student/Month | C23: (ARPU × GM) − Fixed cost share | D23: =(D9*D10)-(Assumptions!C43/Assumptions!C14) -> 262.66667 | E23: =(E9*E10)-(Assumptions!C43/Assumptions!C14) -> 1162.6667 | F23: =E23-D23 -> 900
B24: Break-Even Student Count | C24: Fixed OpEx ÷ Contribution | D24: =Assumptions!C43/D23 -> 12182.741 | E24: =Assumptions!C43/E23 -> 2752.2936 | F24: =D24-E24 -> 9430.4475
B26: VERDICT | C26: CURRENT (Pre-Pivot) | D26: TARGET (Option B)
C27: ="LTV/CAC = " & D21 -> LTV/CAC = 0.3724 | D27: ="LTV/CAC = " & Assumptions!C34 -> LTV/CAC = 1.96444444444444
C28: UNSUSTAINABLE | D28: IMPROVING
B31: GOAL: 3.0× by Month 12 via retention + CAC optimization

Sheet  P&L Model
B2: EduVista — Month-by-Month P&L Model (Months 0 → 12)
B3: M0 = Current State (Pre-Pivot) | M3 = Pilot Launch | M5 = Breakeven Target | M12 = Steady State
B5: Metric (₹ Crores unless stated) | C5: M0 (Current) | D5: M1 | E5: M2 | F5: M3 (Pilot) | G5: M4 | H5: M5 (Breakeven) | I5: M6 | J5: M7 | K5: M8 | L5: M9 | M5: M10 | N5: M11 | O5: M12 (Target)
B6: OPERATING METRICS
B7: Active Students (count) | C7: 2400 | D7: 2400 | E7: 2400 | F7: 3200 | G7: 3800 | H7: 4500 | I7: 5175 | J7: 5900 | K7: 6500 | L7: 7000 | M7: 7200 | N7: 7350 | O7: 7500
B8: Monthly Growth Rate | C8: 0 | D8: 0 | E8: 0 | F8: 0.15 | G8: 0.15 | H8: 0.15 | I8: 0.15 | J8: 0.14 | K8: 0.1 | L8: 0.08 | M8: 0.03 | N8: 0.02 | O8: 0.02
B9: 6-Month Retention Rate | C9: 0.42 | D9: 0.42 | E9: 0.45 | F9: 0.48 | G9: 0.5 | H9: 0.55 | I9: 0.55 | J9: 0.55 | K9: 0.55 | L9: 0.55 | M9: 0.55 | N9: 0.55 | O9: 0.55
B10: Monthly ARPU (₹) | C10: 4200 | D10: 4200 | E10: 4200 | F10: 4500 | G10: 4500 | H10: 4800 | I10: 4800 | J10: 4800 | K10: 4800 | L10: 4800 | M10: 4800 | N10: 4800 | O10: 4800
B12: REVENUE
B13: Total Revenue (₹ Cr) | C13: =C7*C10 -> 10080000 | D13: =D7*D10 -> 10080000 | E13: =E7*E10 -> 10080000 | F13: =F7*F10 -> 14400000 | G13: =G7*G10 -> 17100000 | H13: =H7*H10 -> 21600000 | I13: =I7*I10 -> 24840000 | J13: =J7*J10 -> 28320000 | ... O13: =O7*O10 -> 36000000
B15: COST OF GOODS SOLD (COGS)
B16: Teacher/Content (₹ Cr) | C16: 1400000 | D16: 1400000 | E16: 1400000 | F16: 600000 | G16: 800000 | H16: 900000 | I16: 1000000 | J16: 1200000 | K16: 1300000 | L16: 1400000 | M16: 1400000 | N16: 1500000 | O16: 1500000
B17: Venue/Facilitator (₹ Cr) | C17: 0 | D17: 0 | E17: 0 | F17: 600000 | G17: 600000 | H17: 700000 | I17: 700000 | J17: 700000 | K17: 800000 | L17: 900000 | M17: 900000 | N17: 1000000 | O17: 1000000
B18: Total COGS (₹ Cr) | C18: =C16+C17 -> 1400000 | D18: =D16+D17 -> 1400000 | E18: =E16+E17 -> 1400000 | F18: =F16+F17 -> 1200000 | G18: =G16+G17 -> 1400000 | H18: =H16+H17 -> 1600000 | I18: =I16+I17 -> 1700000 | J18: =J16+J17 -> 1900000 | ... O18: =O16+O17 -> 2500000
B20: GROSS PROFIT
B21: Gross Profit (₹ Cr) | C21: =C13-C18 -> 8680000 | D21: =D13-D18 -> 8680000 | E21: =E13-E18 -> 8680000 | F21: =F13-F18 -> 13200000 | G21: =G13-G18 -> 15700000 | H21: =H13-H18 -> 20000000 | I21: =I13-I18 -> 23140000 | J21: =J13-J18 -> 26420000 | ... O21: =O13-O18 -> 33500000
B22: Gross Margin % | C22: =C21/C13 -> 0.86111111 | D22: =D21/D13 -> 0.86111111 | E22: =E21/E13 -> 0.86111111 | F22: =F21/F13 -> 0.91666667 | G22: =G21/G13 -> 0.91812865 | H22: =H21/H13 -> 0.92592593 | I22: =I21/I13 -> 0.931562 | J22: =J21/J13 -> 0.9329096 | ... O22: =O21/O13 -> 0.93055556
B24: OPERATING EXPENSES
B25: Marketing & CAC Spend (₹ Cr) | C25: 4300000 | D25: 4300000 | E25: 4300000 | F25: 4600000 | G25: 5000000 | H25: 5400000 | I25: 5600000 | J25: 6400000 | K25: 7000000 | L25: 7600000 | M25: 7800000 | N25: 7900000 | O25: 8100000
B26: G&A / Fixed Overhead (₹ Cr) | C26: 3600000 | D26: 3600000 | E26: 3600000 | F26: 3000000 | G26: 2800000 | H26: 2600000 | I26: 2400000 | J26: 2200000 | K26: 2000000 | L26: 1800000 | M26: 1600000 | N26: 1400000 | O26: 1200000
B27: Total OpEx (₹ Cr) | C27: =C25+C26 -> 7900000 | D27: =D25+D26 -> 7900000 | E27: =E25+E26 -> 7900000 | F27: =F25+F26 -> 7600000 | G27: =G25+G26 -> 7800000 | H27: =H25+H26 -> 8000000 | I27: =I25+I26 -> 8000000 | J27: =J25+J26 -> 8600000 | ... O27: =O25+O26 -> 9300000
B29: CONTRIBUTION MARGIN
B30: Contribution Margin (₹ Cr) | C30: 0.08 | D30: 0.08 | E30: 0.08 | F30: 0.56 | G30: 0.79 | H30: 1.2 | I30: 1.51 | J30: 1.78 | K30: 2.01 | L30: 2.19 | M30: 2.29 | N30: 2.35 | O30: 2.42
B31: Cumulative Cash Burn (₹ Cr) | C31: -19.12 | D31: -19.04 | E31: -18.96 | F31: -18.4 | G31: -17.61 | H31: -16.41 | I31: -14.9 | J31: -13.12 | K31: -11.11 | L31: -8.92 | M31: -6.63 | N31: -4.28 | O31: -1.86
B33: ✅ BREAKEVEN at Month 5 — Contribution turns positive at ₹0 Cr | Runway extends 6 → 18 months

Sheet  Scenario Comparison
B2: Strategic Option Comparison — A vs. B vs. C
B3: Option A = Full Hybrid Physical Centers | Option B = Phygital Lite Weekend Hubs ✅ RECOMMENDED | Option C = Recorded-First
B5: Metric | C5: Option A Full Physical Hybrid | D5: Option B Phygital Lite ✅ | E5: Option C Recorded-First | F5: Verdict
B6: INVESTMENT
B7: Setup CapEx (₹ Lakhs) | C7: ₹4.50 Cr | D7: ₹1.25 Cr | E7: ₹30 L | F7: B lowest CapEx
B8: Monthly OpEx (₹ Lakhs) | C8: ₹34.5 L | D8: ₹12.0 L | E8: ₹40.0 L | F8: B optimal
B10: REVENUE AND PRICING
B11: Monthly ARPU (₹) | C11: 5500 | D11: 4800 | E11: 2800 | F11: B balanced value
B12: Students at Scale | C12: 1500 | D12: 4500 | E12: 6000 | F12: B vs C trade-off
B13: Monthly Revenue at Scale (₹ Cr) | C13: ₹0.83 Cr | D13: ₹2.16 Cr | E13: ₹1.68 Cr | F13: B highest revenue
B15: UNIT ECONOMICS
B16: CAC (₹) | C16: 18000 | D16: 10800 | E16: 15000 | F16: B lowest CAC
B17: Gross Margin % | C17: 0.48 | D17: 0.52 | E17: 62% | F17: C highest GM
B18: 6-Month Retention | C18: 0.65 | D18: 55% | E18: 35% | F18: A best retention
B19: LTV/CAC Ratio | C19: 3.5x | D19: 3.2x | E19: 1.4x | F19: B/A viable; C broken
B20: CAC Payback (months) | C20: 18 months | D20: 12 months | E20: 10 months | F20: B meets target
B22: BREAKEVEN AND RISK
B23: Breakeven Month | C23: 8 | D23: 5 | E23: 10 | F23: B fastest viable
B24: Risk Level | C24: HIGH | D24: MEDIUM | E24: HIGH | F24: B lowest risk
B25: Execution Complexity | C25: HIGH | D25: MEDIUM | E25: LOW | F25: C easiest
B26: Scalability | C26: LOW | D26: HIGH | E26: VERY HIGH | F26: C most scalable
B28: VERDICT
B29: Recommendation | C29: ❌ NOT VIABLE. CapEx exceeds runway. Breakeven M8 too late. | D29: ✅ RECOMMENDED. Fastest breakeven (M5). 8-month payback. 55% retention viable. | E29: ⚠️ HIGH RISK. 35% retention → churn spiral. Breakeven M10+ unsustainable. | F29: Option B balances survival + growth
B32: Visual Comparison: Key Metrics by Option
B33: Metric | C33: Option A | D33: Option B | E33: Option C
B34: ARPU (₹00s) | C34: 55 | D34: 48 | E34: 28
B35: Gross Margin % | C35: 48 | D35: 52 | E35: 62
B36: Retention % | C36: 65 | D36: 55 | E36: 35
B37: LTV/CAC (×10) | C37: 35 | D37: 32 | E37: 14
B38: CapEx (₹ Lakh×10) | C38: 45 | D38: 12.5 | E38: 3

Sheet  Sensitivity Analysis
B2: Sensitivity Analysis — LTV/CAC Ratio by CAC × Retention Rate
B3: Assumptions: ARPU = ₹4,800 | Gross Margin = 52% | Avg Lifetime = 1/(1-Retention) | LTV = ARPU × GM × Lifetime | Ratio = LTV ÷ CAC
B5: TABLE 1 — LTV/CAC Ratio | 🔴 < 1x (Bankruptcy) 🟡 1x–3x (At Risk) 🟢 ≥ 3x (Healthy)
B6: CAC (₹)→ / Ret%↓ | C6: 8000 | D6: 10000 | E6: 12000 | F6: 14000 | G6: 16000 | H6: 18000 | I6: 20000 | J6: 22000
B7: 0.3 | C7: =(4800*0.52*(1/(1-$B7^(1/6))))/C$6 -> 1.7160661 | D7: =(4800*0.52*(1/(1-$B7^(1/6))))/D$6 -> 1.3728529 | E7: =(4800*0.52*(1/(1-$B7^(1/6))))/E$6 -> 1.1440441 | F7: =(4800*0.52*(1/(1-$B7^(1/6))))/F$6 -> 0.98060921 | G7: =(4800*0.52*(1/(1-$B7^(1/6))))/G$6 -> 0.85803306 | H7: =(4800*0.52*(1/(1-$B7^(1/6))))/H$6 -> 0.76269605 | I7: =(4800*0.52*(1/(1-$B7^(1/6))))/I$6 -> 0.68642645 | J7: =(4800*0.52*(1/(1-$B7^(1/6))))/J$6 -> 0.62402404
B8: 0.35 | C8: =(4800*0.52*(1/(1-$B8^(1/6))))/C$6 -> 1.9437061 | D8: =(4800*0.52*(1/(1-$B8^(1/6))))/D$6 -> 1.5549649 | E8: =(4800*0.52*(1/(1-$B8^(1/6))))/E$6 -> 1.2958041 | F8: =(4800*0.52*(1/(1-$B8^(1/6))))/F$6 -> 1.1106892 | G8: =(4800*0.52*(1/(1-$B8^(1/6))))/G$6 -> 0.97185306 | H8: =(4800*0.52*(1/(1-$B8^(1/6))))/H$6 -> 0.86386939 | I8: =(4800*0.52*(1/(1-$B8^(1/6))))/I$6 -> 0.77748245 | J8: =(4800*0.52*(1/(1-$B8^(1/6))))/J$6 -> 0.70680223
B9: 0.4 | C9: =(4800*0.52*(1/(1-$B9^(1/6))))/C$6 -> 2.2029887 | D9: =(4800*0.52*(1/(1-$B9^(1/6))))/D$6 -> 1.762391 | E9: =(4800*0.52*(1/(1-$B9^(1/6))))/E$6 -> 1.4686592 | F9: =(4800*0.52*(1/(1-$B9^(1/6))))/F$6 -> 1.2588507 | G9: =(4800*0.52*(1/(1-$B9^(1/6))))/G$6 -> 1.1014944 | H9: =(4800*0.52*(1/(1-$B9^(1/6))))/H$6 -> 0.9791061 | I9: =(4800*0.52*(1/(1-$B9^(1/6))))/I$6 -> 0.88119549 | J9: =(4800*0.52*(1/(1-$B9^(1/6))))/J$6 -> 0.80108681
B10: 0.45 | C10: =(4800*0.52*(1/(1-$B10^(1/6))))/C$6 -> 2.5038323 | D10: =(4800*0.52*(1/(1-$B10^(1/6))))/D$6 -> 2.0030659 | E10: =(4800*0.52*(1/(1-$B10^(1/6))))/E$6 -> 1.6692216 | F10: =(4800*0.52*(1/(1-$B10^(1/6))))/F$6 -> 1.4307613 | G10: =(4800*0.52*(1/(1-$B10^(1/6))))/G$6 -> 1.2519162 | H10: =(4800*0.52*(1/(1-$B10^(1/6))))/H$6 -> 1.1128144 | I10: =(4800*0.52*(1/(1-$B10^(1/6))))/I$6 -> 1.0015329 | J10: =(4800*0.52*(1/(1-$B10^(1/6))))/J$6 -> 0.91048448
B11: 0.5 | C11: =(4800*0.52*(1/(1-$B11^(1/6))))/C$6 -> 2.8597281 | D11: =(4800*0.52*(1/(1-$B11^(1/6))))/D$6 -> 2.2877825 | E11: =(4800*0.52*(1/(1-$B11^(1/6))))/E$6 -> 1.9064854 | F11: =(4800*0.52*(1/(1-$B11^(1/6))))/F$6 -> 1.6341303 | G11: =(4800*0.52*(1/(1-$B11^(1/6))))/G$6 -> 1.429864 | H11: =(4800*0.52*(1/(1-$B11^(1/6))))/H$6 -> 1.2709903 | I11: =(4800*0.52*(1/(1-$B11^(1/6))))/I$6 -> 1.1438912 | J11: =(4800*0.52*(1/(1-$B11^(1/6))))/J$6 -> 1.0399011
B12: 0.55 | C12: =(4800*0.52*(1/(1-$B12^(1/6))))/C$6 -> 3.2898785 | D12: =(4800*0.52*(1/(1-$B12^(1/6))))/D$6 -> 2.6319028 | E12: =(4800*0.52*(1/(1-$B12^(1/6))))/E$6 -> 2.1932523 | F12: =(4800*0.52*(1/(1-$B12^(1/6))))/F$6 -> 1.8799306 | G12: =(4800*0.52*(1/(1-$B12^(1/6))))/G$6 -> 1.6449392 | H12: =(4800*0.52*(1/(1-$B12^(1/6))))/H$6 -> 1.4621682 | I12: =(4800*0.52*(1/(1-$B12^(1/6))))/I$6 -> 1.3159514 | J12: =(4800*0.52*(1/(1-$B12^(1/6))))/J$6 -> 1.1963195
B13: 0.6 | C13: =(4800*0.52*(1/(1-$B13^(1/6))))/C$6 -> 3.8228689 | D13: =(4800*0.52*(1/(1-$B13^(1/6))))/D$6 -> 3.0582952 | E13: =(4800*0.52*(1/(1-$B13^(1/6))))/E$6 -> 2.5485793 | F13: =(4800*0.52*(1/(1-$B13^(1/6))))/F$6 -> 2.1844965 | G13: =(4800*0.52*(1/(1-$B13^(1/6))))/G$6 -> 1.9114345 | H13: =(4800*0.52*(1/(1-$B13^(1/6))))/H$6 -> 1.6990529 | I13: =(4800*0.52*(1/(1-$B13^(1/6))))/I$6 -> 1.5291476 | J13: =(4800*0.52*(1/(1-$B13^(1/6))))/J$6 -> 1.3901342
B14: 0.65 | C14: =(4800*0.52*(1/(1-$B14^(1/6))))/C$6 -> 4.5034428 | D14: =(4800*0.52*(1/(1-$B14^(1/6))))/D$6 -> 3.6027542 | E14: =(4800*0.52*(1/(1-$B14^(1/6))))/E$6 -> 3.0022952 | F14: =(4800*0.52*(1/(1-$B14^(1/6))))/F$6 -> 2.5733959 | G14: =(4800*0.52*(1/(1-$B14^(1/6))))/G$6 -> 2.2517214 | H14: =(4800*0.52*(1/(1-$B14^(1/6))))/H$6 -> 2.0015301 | I14: =(4800*0.52*(1/(1-$B14^(1/6))))/I$6 -> 1.8013771 | J14: =(4800*0.52*(1/(1-$B14^(1/6))))/J$6 -> 1.6376156
B15: 0.7 | C15: =(4800*0.52*(1/(1-$B15^(1/6))))/C$6 -> 5.4060218 | D15: =(4800*0.52*(1/(1-$B15^(1/6))))/D$6 -> 4.3248175 | E15: =(4800*0.52*(1/(1-$B15^(1/6))))/E$6 -> 3.6040146 | F15: =(4800*0.52*(1/(1-$B15^(1/6))))/F$6 -> 3.0891553 | G15: =(4800*0.52*(1/(1-$B15^(1/6))))/G$6 -> 2.7030109 | H15: =(4800*0.52*(1/(1-$B15^(1/6))))/H$6 -> 2.4026764 | I15: =(4800*0.52*(1/(1-$B15^(1/6))))/I$6 -> 2.1624087 | J15: =(4800*0.52*(1/(1-$B15^(1/6))))/J$6 -> 1.9658261
B17: Breakeven Students by ARPU × Gross Margin
B18: ARPU→ / GM↓ | C18: 3000 | D18: 3500 | E18: 4000 | F18: 4200 | G18: 4500 | H18: 4800 | I18: 5000 | J18: 5500
B19: 0.35 | C19: =1200000/(C$18*$B19) -> 1142.8571 | D19: =1200000/(D$18*$B19) -> 979.59184 | E19: =1200000/(E$18*$B19) -> 857.14286 | F19: =1200000/(F$18*$B19) -> 816.32653 | G19: =1200000/(G$18*$B19) -> 761.90476 | H19: =1200000/(H$18*$B19) -> 714.28571 | I19: =1200000/(I$18*$B19) -> 685.71429 | J19: =1200000/(J$18*$B19) -> 623.37662
B20: 0.4 | C20: =1200000/(C$18*$B20) -> 1000 | D20: =1200000/(D$18*$B20) -> 857.14286 | E20: =1200000/(E$18*$B20) -> 750 | F20: =1200000/(F$18*$B20) -> 714.28571 | G20: =1200000/(G$18*$B20) -> 666.66667 | H20: =1200000/(H$18*$B20) -> 625 | I20: =1200000/(I$18*$B20) -> 600 | J20: =1200000/(J$18*$B20) -> 545.45455
B21: 0.45 | C21: =1200000/(C$18*$B21) -> 888.88889 | D21: =1200000/(D$18*$B21) -> 761.90476 | E21: =1200000/(E$18*$B21) -> 666.66667 | F21: =1200000/(F$18*$B21) -> 634.92063 | G21: =1200000/(G$18*$B21) -> 592.59259 | H21: =1200000/(H$18*$B21) -> 555.55556 | I21: =1200000/(I$18*$B21) -> 533.33333 | J21: =1200000/(J$18*$B21) -> 484.84848
B22: 0.48 | C22: =1200000/(C$18*$B22) -> 833.33333 | D22: =1200000/(D$18*$B22) -> 714.28571 | E22: =1200000/(E$18*$B22) -> 625 | F22: =1200000/(F$18*$B22) -> 595.2381 | G22: =1200000/(G$18*$B22) -> 555.55556 | H22: =1200000/(H$18*$B22) -> 520.83333 | I22: =1200000/(I$18*$B22) -> 500 | J22: =1200000/(J$18*$B22) -> 454.54545
B23: 0.5 | C23: =1200000/(C$18*$B23) -> 800 | D23: =1200000/(D$18*$B23) -> 685.71429 | E23: =1200000/(E$18*$B23) -> 600 | F23: =1200000/(F$18*$B23) -> 571.42857 | G23: =1200000/(G$18*$B23) -> 533.33333 | H23: =1200000/(H$18*$B23) -> 500 | I23: =1200000/(I$18*$B23) -> 480 | J23: =1200000/(J$18*$B23) -> 436.36364
B24: 0.52 | C24: =1200000/(C$18*$B24) -> 769.23077 | D24: =1200000/(D$18*$B24) -> 659.34066 | E24: =1200000/(E$18*$B24) -> 576.92308 | F24: =1200000/(F$18*$B24) -> 549.45055 | G24: =1200000/(G$18*$B24) -> 512.82051 | H24: =1200000/(H$18*$B24) -> 480.76923 | I24: =1200000/(I$18*$B24) -> 461.53846 | J24: =1200000/(J$18*$B24) -> 419.58042
B25: 0.55 | C25: =1200000/(C$18*$B25) -> 727.27273 | D25: =1200000/(D$18*$B25) -> 623.37662 | E25: =1200000/(E$18*$B25) -> 545.45455 | F25: =1200000/(F$18*$B25) -> 519.48052 | G25: =1200000/(G$18*$B25) -> 484.84848 | H25: =1200000/(H$18*$B25) -> 454.54545 | I25: =1200000/(I$18*$B25) -> 436.36364 | J25: =1200000/(J$18*$B25) -> 396.69421
B26: 0.6 | C26: =1200000/(C$18*$B26) -> 666.66667 | D26: =1200000/(D$18*$B26) -> 571.42857 | E26: =1200000/(E$18*$B26) -> 500 | F26: =1200000/(F$18*$B26) -> 476.19048 | G26: =1200000/(G$18*$B26) -> 444.44444 | H26: =1200000/(H$18*$B26) -> 416.66667 | I26: =1200000/(I$18*$B26) -> 400 | J26: =1200000/(J$18*$B26) -> 363.63636
B27: 0.65 | C27: =1200000/(C$18*$B27) -> 615.38462 | D27: =1200000/(D$18*$B27) -> 527.47253 | E27: =1200000/(E$18*$B27) -> 461.53846 | F27: =1200000/(F$18*$B27) -> 439.56044 | G27: =1200000/(G$18*$B27) -> 410.25641 | H27: =1200000/(H$18*$B27) -> 384.61538 | I27: =1200000/(I$18*$B27) -> 369.23077 | J27: =1200000/(J$18*$B27) -> 335.66434
B29: 📍 Current: ARPU=₹4,200 | CAC=₹18,000 | Retention=42% → RED zone | 📍 Target: ARPU=₹4,800 | Retention=55% → YELLOW zone | 📍 Goal: Retention ≥70% → GREEN zone

Sheet  Competitive Intel
B2: Indian K-12 EdTech — Competitive Benchmark Dashboard
B3: Metric | C3: PhysicsWallah | D3: Unacademy | E3: Allen CI | F3: EduVista Target
B4: PRICING
B5: Annual ARPU – Online (₹) | C5: 4000 | D5: ₹8,000–15,000 | E5: ₹10,000–20,000 | F5: ₹3,000–5,000
B6: Annual ARPU – Offline (₹) | C6: ₹65,000 | D6: N/A | E6: ₹77,000–3,50,000 | F6: ₹50,000–60,000
B8: ACQUISITION
B9: CAC (₹) | C9: ~₹0 | D9: ₹12,000–18,000 | E9: ₹3,000–5,000 | F9: <₹10,800
B10: Payback Period | C10: 3–6 months | D10: >24 months | E10: 12–18 months | F10: <12 months
B12: MARGINS
B13: Gross Margin | C13: 65–70% | D13: 40–50% | E13: 55–65% | F13: 52%(M5)
B14: EBITDA Margin | C14: 10–15% | D14: Negative | E14: 8–12% | F14: +10% (Y2)
B15: Net Profit/Loss FY25 | C15: Breakeven | D15: (₹436 Cr) | E15: ₹41 Cr | F15: Early Stage
B17: RETENTION & LTV
B18: 6-Mo Retention – Online | C18: N/A (hybrid) | D18: 55–60% | E18: N/A | F18: Target: 55%
B19: 6-Mo Retention – Hybrid | C19: 65–70% | D19: N/A | E19: 70–75% | F19: Target: 65% (Phase 2)
B20: LTV:CAC Ratio | C20: >10× ✅ | D20: 0.5x ❌ | E20: 4x ✅ | F20: 1.97× (Phase 1)
B22: SCALE
B23: Revenue FY25 | C23: ₹2,887 Cr | D23: ₹826 Cr | E23: ₹3,067 Cr | F23: Early Stage
B24: Student Base | C24: ~50L registered | D24: ~35L registered | E24: ~8L classroom | F24: 2,400 → 7,500
B25: Key Advantage | C25: Near-zero CAC + Youtube | D25: Scale + Brand | E25: Legacy Brand | F25: Tier 2 + Phygital
B28: GAP vs PW: CAC ₹18K → ₹10.8K (−40%) | Retention 42% → 55% (+13pp) | LTV/CAC 0.82× → 1.97× → Long-term target: 3× (PW benchmark = >10×)
B30: Sources: Inc42 Annual Report 2025 | PW DRHP | Economic Times | RaySolute Research | April 2026
